Workbook

Sheet フォームの回答 1
A1: タイムスタンプ | B1: 店名 | C1: 大正酔いどれクエストⅡに参加されますか？ | D1: エリア | E1: カテゴリ | F1: スタイル | G1: タイプ | H1: テイクアウト | I1: どれクエ対応曜日 | J1: どれクエ対応時間：開始 | K1: どれクエ対応時間：終了 | L1: 提供時間に対する補足 | M1: 決済方法 | N1: 店舗クーポンを希望されますか？ | O1: 「どれクエⅡ」にはどの企画で参加されますか？ | P1: 酔いどれセット名 | Q1: 酔いどれセット内容 | R1: セット内容備考 | S1: 価格(税込) | T1: チャージ料(税込) | U1: 限定数量 | V1: クエスト名 | W1: クエスト内容/報酬 | X1: クエスト料金(税込) | Y1: クエストチャージ料 (税込) | Z1: クエスト備考 | AA1: 酔いどれセット名 | AB1: 酔いどれセット内容 2 | AC1: セット内容備考 2 | AD1: 価格(税込) | AE1: チャージ料(税込) 2 | AF1: 限定数量 2 | AG1: クエスト名 2 | AH1: クエスト内容/報酬 2 | AI1: クエスト料金(税込) 2 | AJ1: クエストチャージ料 (税込) 2 | AK1: クエスト備考 2 | AL1: お客様向け参加証(缶バッチ) 販売希望数は？ | AM1: ID | AN1: キャッチコピー | AO1: Instagram | AP1: 住所 | AQ1: googlemap | AR1: 特定日
A2: 46280.631 | B2: Tようび | C2: 参加する | D2: 三軒家西 | E2: おばんざい | F2: テールブあり | G2: サク飲み | H2: テイクアウトOK | I2: 日曜日, 火曜日, 水曜日, 木曜日, 金曜日, 土曜日 | J2: 0.70833333 | K2: 0.91666667 | L2: 土日祝は15時～22時 | M2: 現金, paypay, クレジットカード, d払い、楽天pay、aupay、wesmo | N2: はい。希望します。 | O2: 「酔いどれセット」のみで参加 | P2: 選べるおばんざい3種セット | Q2: おばんざい小盛3種+ドリンク1杯 | R2: 数種類あるおばんざいから3種類選べます。 | S2: 800 | T2: 酔いどれセットの方は０円 | U2: おばんざいが無くなるまで。 | AM2: {=_xlfn.XLOOKUP($B2,'シート1'!$B$2:$B$70,'シート1'!$A$2:$A$70,"",0,1)} -> 1 | AN2: {=_xlfn.XLOOKUP($B2,'シート1'!$B$2:$B$70,'シート1'!C$2:C$70,"",0,1)} -> 牛すじとお酒とおばんざい | AO2: {=_xlfn.XLOOKUP($B2,'シート1'!$B$2:$B$70,'シート1'!D$2:D$70,"",0,1)} -> https://www.instagram.com/t_youbi_ | AP2: {=_xlfn.XLOOKUP($B2,'シート1'!$B$2:$B$70,'シート1'!E$2:E$70,"",0,1)} -> 大阪市大正区三軒家西１丁目４−１５ 大正コペンシルビル 2F | AQ2: {=_xlfn.XLOOKUP($B2,'シート1'!$B$2:$B$70,'シート1'!F$2:F$70,"",0,1)} -> https://maps.app.goo.gl/zEmF7y9d2rdJpG8a7
A3: 46291.663 | B3: ハイエナハイツ | C3: 参加する | D3: 駅前 | E3: ジビエ肉 | F3: テーブルあり | G3: 腹ごしらえ | H3: テイクアウトOK | I3: 日曜日, 火曜日, 水曜日, 木曜日, 金曜日, 土曜日 | J3: 0.70833333 | K3: 0.95833333 | L3: 週末延長可能性あり | M3: 現金, paypay | N3: はい。希望します。 | O3: 「酔いどれセット」のみで参加 | P3: 一品とお酒 | Q3: 一品とお酒 | R3: 一品とお酒 | S3: 1000 | T3: 0 | U3: 限定30セット / 日 | AL3: 30 | AM3: {=_xlfn.XLOOKUP($B3,'シート1'!$B$2:$B$70,'シート1'!$A$2:$A$70,"",0,1)} -> 5 | AN3: {=_xlfn.XLOOKUP($B3,'シート1'!$B$2:$B$70,'シート1'!C$2:C$70,"",0,1)} -> ジビエ・肉料理 | AO3: {=_xlfn.XLOOKUP($B3,'シート1'!$B$2:$B$70,'シート1'!D$2:D$70,"",0,1)} -> https://www.instagram.com/haiena_haitu | AP3: {=_xlfn.XLOOKUP($B3,'シート1'!$B$2:$B$70,'シート1'!E$2:E$70,"",0,1)} -> 大阪市大正区三軒家西１丁目５−７ | AQ3: {=_xlfn.XLOOKUP($B3,'シート1'!$B$2:$B$70,'シート1'!F$2:F$70,"",0,1)} -> https://maps.app.goo.gl/JVXGfL5NwG4vKz2t6
A4: 46292.642 | B4: CHWEETS キイロのお店 | C4: 参加する | D4: 三軒家西 | E4: カフェ | F4: テーブルあり | G4: ひと休み | H4: テイクアウトOK | I4: 火曜日, 水曜日, 木曜日, 金曜日, 土曜日 | J4: 0.79166667 | K4: 0.95833333 | L4: LO 22:30 | M4: 現金 | N4: はい。希望します。 | O4: 「酔いどれセット」のみで参加 | P4: オレオピロークレープとハンドドリップコーヒー(自家製生チョコ付き) | Q4: 包みタイプのクレープとハンドドリップコーヒー(自家製生チョコ付き)のセットです | S4: 1000 | T4: 0 | AL4: 15 | AM4: {=_xlfn.XLOOKUP($B4,'シート1'!$B$2:$B$70,'シート1'!$A$2:$A$70,"",0,1)} -> 6 | AN4: {=_xlfn.XLOOKUP($B4,'シート1'!$B$2:$B$70,'シート1'!C$2:C$70,"",0,1)} -> クレープ酒場・夜カフェ | AO4: {=_xlfn.XLOOKUP($B4,'シート1'!$B$2:$B$70,'シート1'!D$2:D$70,"",0,1)} -> https://www.instagram.com/chweets_1138 | AP4: {=_xlfn.XLOOKUP($B4,'シート1'!$B$2:$B$70,'シート1'!E$2:E$70,"",0,1)} -> 大阪市大正区三軒家西１丁目１７−１７ | AQ4: {=_xlfn.XLOOKUP($B4,'シート1'!$B$2:$B$70,'シート1'!F$2:F$70,"",0,1)} -> https://maps.app.goo.gl/rBmQt912byGEZgbU7
A5: 46295.489 | B5: ナンチャッ亭のエリー | C5: 参加する | D5: 三軒家東 | E5: おばんざい | F5: カウンター | G5: サク飲み | H5: テイクアウト不可 | I5: 日曜日, 月曜日, 木曜日, 金曜日, 土曜日 | J5: 0.72916667 | K5: 0.95833333 | M5: 現金 | N5: はい。希望します。 | O5: 「酔いどれセット」のみで参加 | P5: 一休みセット | Q5: ひと口おばんざいセットと1ドリンク | R5: お腹に優しいおばんざいひと口サイズの盛り合わせ | S5: 800 | T5: 0 | U5: 限定30 | AL5: 30 | AM5: {=_xlfn.XLOOKUP($B5,'シート1'!$B$2:$B$70,'シート1'!$A$2:$A$70,"",0,1)} -> 16 | AN5: {=_xlfn.XLOOKUP($B5,'シート1'!$B$2:$B$70,'シート1'!C$2:C$70,"",0,1)} -> 昭和レトロなおばんざい | AO5: {=_xlfn.XLOOKUP($B5,'シート1'!$B$2:$B$70,'シート1'!D$2:D$70,"",0,1)} -> https://www.instagram.com/nanchatteino_erie | AP5: {=_xlfn.XLOOKUP($B5,'シート1'!$B$2:$B$70,'シート1'!E$2:E$70,"",0,1)} -> 大阪市大正区三軒家東１丁目１７−３３ 平和相互商事大正橋ビル 1F | AQ5: {=_xlfn.XLOOKUP($B5,'シート1'!$B$2:$B$70,'シート1'!F$2:F$70,"",0,1)} -> https://maps.app.goo.gl/kGdEWrLq5bwaRyeX7
A6: 46295.57 | B6: バーガー酒場ハンバーガー・ママ | C6: 参加する | D6: 駅前 | E6: ハンバーガー | F6: カウンター | G6: サク飲み | H6: テイクアウト不可 | I6: 月曜日, 火曜日, 水曜日, 木曜日, 金曜日, 土曜日 | J6: 0.5 | K6: 0 | L6: 火・木は18:00オープン | M6: 現金, paypay, クレジットカード, 各種QR決済 | N6: はい。希望します。 | O6: 「酔いどれセット」のみで参加 | P6: どれクエII限定ミニバーガー＋ドリンクセット | Q6: イベント期間限定ミニバーガー＋ちょいポテト＋1ドリンク | S6: 1000 | T6: 0 | AL6: 20 | AM6: {=_xlfn.XLOOKUP($B6,'シート1'!$B$2:$B$70,'シート1'!$A$2:$A$70,"",0,1)} -> 2 | AN6: {=_xlfn.XLOOKUP($B6,'シート1'!$B$2:$B$70,'シート1'!C$2:C$70,"",0,1)} -> 一品と酒とグルメバーガー | AO6: {=_xlfn.XLOOKUP($B6,'シート1'!$B$2:$B$70,'シート1'!D$2:D$70,"",0,1)} -> https://www.instagram.com/hamburger.mama | AP6: {=_xlfn.XLOOKUP($B6,'シート1'!$B$2:$B$70,'シート1'!E$2:E$70,"",0,1)} -> 大阪市大正区三軒家東１丁目１０−２０ | AQ6: {=_xlfn.XLOOKUP($B6,'シート1'!$B$2:$B$70,'シート1'!F$2:F$70,"",0,1)} -> https://maps.app.goo.gl/LvrTR4thHgoGpoRc7
A7: 46295.621 | B7: BARカセット | C7: 参加する | D7: 三軒家東 | E7: BAR | F7: カウンター | G7: 夜遊び | H7: テイクアウト不可 | I7: 全て | J7: 0.875 | K7: 0.125 | L7: 店舗STAFFのシフトにより若干の時間変動あり | M7: 現金 | N7: はい。希望します。 | O7: 「酔いどれセット」・「店舗クエスト」両方で参加 | AA7: ぐんたいガニ捕獲セット（カニぱん） | AB7: ドリンクを注文したお客様に三立製菓さんの「かにパン」をプレゼント！ | AC7: 店頭で捕獲したぐんたいガ二（かにパン）は、その場で食べても良し！持ち帰って、明日のパンにしても良し！ | AD7: 1000 | AE7: 500 | AF7: 30セット予定（好評の場合追加有り） | AG7: ぐんたいガニ乱獲クエスト | AH7: 追加ドリンクを注文して頂いたお客様に「勇者のサイコロ」でSTAFFに挑戦して貰います。見事STAFFに勝利したお客様には三立製菓さんの「かにビス」をプレゼント！ | AI7: 500～900 | AJ7: 追加ドリンクの料金のみ | AK7: スコッチ以外のドリンクで、酔いどれセットご注文、又は2杯目以降のご注文から挑戦して頂けます | AL7: 15 | AM7: {=_xlfn.XLOOKUP($B7,'シート1'!$B$2:$B$70,'シート1'!$A$2:$A$70,"",0,1)} -> 19 | AN7: {=_xlfn.XLOOKUP($B7,'シート1'!$B$2:$B$70,'シート1'!C$2:C$70,"",0,1)} -> 80's・ロック・駄菓子 | AO7: {=_xlfn.XLOOKUP($B7,'シート1'!$B$2:$B$70,'シート1'!D$2:D$70,"",0,1)} -> https://www.instagram.com/showz0069 | AP7: {=_xlfn.XLOOKUP($B7,'シート1'!$B$2:$B$70,'シート1'!E$2:E$70,"",0,1)} -> 大阪市大正区三軒家東１丁目２−５ 1F | AQ7: {=_xlfn.XLOOKUP($B7,'シート1'!$B$2:$B$70,'シート1'!F$2:F$70,"",0,1)} -> https://maps.app.goo.gl/uUPFxJA4w57PqYzf7
A8: 46295.811 | B8: Bar Six Nine | C8: 参加する | D8: 三軒家東 | E8: BAR | F8: テーブルあり | G8: 夜遊び | H8: テイクアウト不可 | I8: 全て | J8: 0.83333333 | K8: 0.125 | M8: 現金 | N8: いいえ、希望しません。 | O8: 「酔いどれセット」のみで参加 | P8: 1000円セット | Q8: ドリンク1杯+おつまみ | S8: 1000 | AL8: 5 | AM8: {=_xlfn.XLOOKUP($B8,'シート1'!$B$2:$B$70,'シート1'!$A$2:$A$70,"",0,1)} -> 8 | AN8: {=_xlfn.XLOOKUP($B8,'シート1'!$B$2:$B$70,'シート1'!C$2:C$70,"",0,1)} -> ショットバー | AO8: {=_xlfn.XLOOKUP($B8,'シート1'!$B$2:$B$70,'シート1'!D$2:D$70,"",0,1)} -> https://www.instagram.com/bar_six_nine_0692 | AP8: {=_xlfn.XLOOKUP($B8,'シート1'!$B$2:$B$70,'シート1'!E$2:E$70,"",0,1)} -> 大阪市大正区三軒家東１丁目５ | AQ8: {=_xlfn.XLOOKUP($B8,'シート1'!$B$2:$B$70,'シート1'!F$2:F$70,"",0,1)} -> https://maps.app.goo.gl/j4hhdwnWPQZ365rk7
A9: 46295.917 | B9: SoundBar花いち | C9: 参加する | D9: 駅前 | E9: BAR | F9: カウンター | G9: 夜遊び | H9: テイクアウト不可 | I9: 全て | J9: 0.875 | K9: 0.083333333 | L9: その日の状況により早く閉める場合あり。 | M9: 現金 | N9: いいえ、希望しません。 | O9: 「酔いどれセット」・「店舗クエスト」両方で参加 | AA9: 花いちオリジナルセット | AB9: 700円までのドリンク1杯+チャーム+カラオケ無料 | AC9: 特になし | AD9: 1000 | AE9: なし | AF9: 特になし | AG9: カラオケで95点以上にチャレンジ！！ | AH9: カラオケで95点以上出した方に、〆のカップ麺1個プレゼント！！ | AI9: なし | AJ9: なし | AL9: 5 | AM9: {=_xlfn.XLOOKUP($B9,'シート1'!$B$2:$B$70,'シート1'!$A$2:$A$70,"",0,1)} -> 27 | AN9: {=_xlfn.XLOOKUP($B9,'シート1'!$B$2:$B$70,'シート1'!C$2:C$70,"",0,1)} -> カラオケバー | AO9: {=_xlfn.XLOOKUP($B9,'シート1'!$B$2:$B$70,'シート1'!D$2:D$70,"",0,1)} -> https://www.instagram.com/soundbar__hanaichi | AP9: {=_xlfn.XLOOKUP($B9,'シート1'!$B$2:$B$70,'シート1'!E$2:E$70,"",0,1)} -> 大阪市大正区三軒家東１丁目５−１４ 2階 | AQ9: {=_xlfn.XLOOKUP($B9,'シート1'!$B$2:$B$70,'シート1'!F$2:F$70,"",0,1)} -> https://maps.app.goo.gl/typkWCnoPJKCUWyH8
A10: 46296.498 | B10: 大正バル誠~ｓｅｉ~ | C10: 参加する | D10: 駅前 | E10: 居酒屋 | F10: テーブルあり | G10: 腹ごしらえ | H10: テイクアウト不可 | I10: 全て | J10: 0.75 | K10: 0.91666667 | L10: 22時以降も席とお店が開いていればOK | M10: 現金, paypay, クレジットカード | N10: いいえ、希望しません。 | O10: 「酔いどれセット」のみで参加 | P10: 誠seiセット | Q10: ワンドリンク＋串カツ５本or牡蠣セット | S10: 1000 | AL10: 10 | AM10: {=_xlfn.XLOOKUP($B10,'シート1'!$B$2:$B$70,'シート1'!$A$2:$A$70,"",0,1)} -> 12 | AN10: {=_xlfn.XLOOKUP($B10,'シート1'!$B$2:$B$70,'シート1'!C$2:C$70,"",0,1)} -> 串カツ・牡蠣・沖縄料理 | AO10: {=_xlfn.XLOOKUP($B10,'シート1'!$B$2:$B$70,'シート1'!D$2:D$70,"",0,1)} -> https://www.instagram.com/izakaya_sei | AP10: {=_xlfn.XLOOKUP($B10,'シート1'!$B$2:$B$70,'シート1'!E$2:E$70,"",0,1)} -> 大阪市大正区三軒家東１丁目３−１１ | AQ10: {=_xlfn.XLOOKUP($B10,'シート1'!$B$2:$B$70,'シート1'!F$2:F$70,"",0,1)} -> https://maps.app.goo.gl/2TSaY99KjvafbH728
A11: 46296.538 | B11: 大正居酒屋タイガーパンチ | C11: 参加する | D11: 駅前 | E11: 中華メインの居酒屋 | F11: 1F立ち飲み2Fテーブル | G11: サク飲み | H11: テイクアウトOK | I11: 全て | J11: 0.625 | K11: 0.91666667 | M11: 現金, paypay | N11: はい。希望します。 | O11: 「酔いどれセット」・「店舗クエスト」両方で参加 | AA11: 元気玉セット | AB11: 元気玉+黒糖焼酎（じょうご）一杯 | AD11: 1000 | AE11: 330 | AG11: 未定 | AH11: 未定 | AI11: 未定 | AL11: 10 | AM11: {=_xlfn.XLOOKUP($B11,'シート1'!$B$2:$B$70,'シート1'!$A$2:$A$70,"",0,1)} -> 4 | AN11: {=_xlfn.XLOOKUP($B11,'シート1'!$B$2:$B$70,'シート1'!C$2:C$70,"",0,1)} -> 創作ガチ中華 | AO11: {=_xlfn.XLOOKUP($B11,'シート1'!$B$2:$B$70,'シート1'!D$2:D$70,"",0,1)} -> https://www.instagram.com/taipan_taisho | AP11: {=_xlfn.XLOOKUP($B11,'シート1'!$B$2:$B$70,'シート1'!E$2:E$70,"",0,1)} -> 大阪市大正区三軒家東１丁目５−１３ | AQ11: {=_xlfn.XLOOKUP($B11,'シート1'!$B$2:$B$70,'シート1'!F$2:F$70,"",0,1)} -> https://maps.app.goo.gl/wSUzPpSDHh3tzyap6
A12: 46296.624 | B12: 大正焼肉SUNナスビ!! | C12: 参加する | D12: 駅前 | E12: 焼肉・ホルモン | F12: テーブルあり | G12: 腹ごしらえ | H12: テイクアウト不可 | I12: 全て | J12: 0.625 | K12: 0.91666667 | M12: 現金, paypay, クレジットカード, 電子マネー | N12: はい。希望します。 | O12: 「酔いどれセット」・「店舗クエスト」両方で参加 | AA12: 選べる名物厚切り肉！ | AB12: 好きなドリンク1杯と名物の厚切り上塩タンか厚切り特上ハラミどちらかを選んでもらえるセット | AC12: 酔いどれセットのテイクアウト不可 | AD12: 2000 | AE12: 0 | AF12: 期間中いつでも可 | AG12: ピンゾロチャレンジ | AH12: サイコロで1のゾロ目が出たら酔いどれセットが半額になる | AI12: 0 | AL12: 10 | AM12: {=_xlfn.XLOOKUP($B12,'シート1'!$B$2:$B$70,'シート1'!$A$2:$A$70,"",0,1)} -> 3 | AN12: {=_xlfn.XLOOKUP($B12,'シート1'!$B$2:$B$70,'シート1'!C$2:C$70,"",0,1)} -> 通える高級焼肉 | AO12: {=_xlfn.XLOOKUP($B12,'シート1'!$B$2:$B$70,'シート1'!D$2:D$70,"",0,1)} -> https://www.instagram.com/sunnasubi0675085821 | AP12: {=_xlfn.XLOOKUP($B12,'シート1'!$B$2:$B$70,'シート1'!E$2:E$70,"",0,1)} -> 大阪市大正区三軒家東１丁目５−１０ | AQ12: {=_xlfn.XLOOKUP($B12,'シート1'!$B$2:$B$70,'シート1'!F$2:F$70,"",0,1)} -> https://maps.app.goo.gl/9DHWbdXcG6VwQRg17
A13: 46300.615 | B13: Bar Coco-Color | C13: 参加する | D13: 三軒家西 | E13: BAR | F13: カウンター | G13: サク飲み | H13: テイクアウト不可 | I13: 全て | J13: 0.83333333 | K13: 0.14583333 | L13: 3:30飲み放題ラストオーダー、4:30で終了、退店 | M13: 現金, クレジットカード, Paypay、D払い以外のバーコード決済 | N13: はい。希望します。 | O13: 「酔いどれセット」のみで参加 | P13: 1H飲み放題1000円 | Q13: 1H飲み放題1000円(チャージ料込み) | R13: ラストオーダー15分前、入店3:30まで | S13: 1000 | AL13: 15 | AM13: {=_xlfn.XLOOKUP($B13,'シート1'!$B$2:$B$70,'シート1'!$A$2:$A$70,"",0,1)} -> 30 | AN13: {=_xlfn.XLOOKUP($B13,'シート1'!$B$2:$B$70,'シート1'!C$2:C$70,"",0,1)} -> カジュアルバー | AO13: {=_xlfn.XLOOKUP($B13,'シート1'!$B$2:$B$70,'シート1'!D$2:D$70,"",0,1)} -> https://www.instagram.com/bar_cococolor_taisho | AP13: {=_xlfn.XLOOKUP($B13,'シート1'!$B$2:$B$70,'シート1'!E$2:E$70,"",0,1)} -> 大阪市大正区三軒家西１丁目１６−１６ | AQ13: {=_xlfn.XLOOKUP($B13,'シート1'!$B$2:$B$70,'シート1'!F$2:F$70,"",0,1)} -> https://maps.app.goo.gl/95uXqnFcfkMM8Jwo8
A14: 46304.761 | B14: 9回の表 | C14: 参加する | D14: 泉尾 | E14: BAR | F14: カウンター | G14: 夜遊び | H14: テイクアウト不可 | I14: 全て | J14: 0.8125 | K14: 0.99305556 | M14: 現金, paypay | N14: はい。希望します。 | O14: 「酔いどれセット」・「店舗クエスト」両方で参加 | AA14: ドラクエ限定 一杯目100円 | AB14: 入店1杯目100円 | AD14: 100 | AE14: 0 | AF14: 無し | AG14: 立体四目並べ 勝てば、1杯無料 | AH14: 勝てば1杯無料 | AI14: 100 | AJ14: 0 | AL14: 20 | AM14: {=_xlfn.XLOOKUP($B14,'シート1'!$B$2:$B$70,'シート1'!$A$2:$A$70,"",0,1)} -> 42 | AN14: {=_xlfn.XLOOKUP($B14,'シート1'!$B$2:$B$70,'シート1'!C$2:C$70,"",0,1)} -> 生演奏で歌えるバー | AO14: {=_xlfn.XLOOKUP($B14,'シート1'!$B$2:$B$70,'シート1'!D$2:D$70,"",0,1)} -> https://www.instagram.com/9kaino_omote | AP14: {=_xlfn.XLOOKUP($B14,'シート1'!$B$2:$B$70,'シート1'!E$2:E$70,"",0,1)} -> 大阪市大正区泉尾４丁目４−１ | AQ14: {=_xlfn.XLOOKUP($B14,'シート1'!$B$2:$B$70,'シート1'!F$2:F$70,"",0,1)} -> https://maps.app.goo.gl/omY9WnpdAGAU7iFX6
A15: 46304.853 | B15: かのじょとカレー | C15: 参加する | D15: 泉尾 | E15: スパイスカレー | F15: カウンター | G15: 昼飲み | H15: テイクアウトOK | I15: 土曜日 | J15: 0.47916667 | K15: 0.64583333 | L15: 1月30日(土)のみ営業 15時ラストオーダー | M15: 現金 | N15: はい。希望します。 | O15: 「酔いどれセット」・「店舗クエスト」両方で参加 | AA15: 酔いどれカレー | AB15: チキンスパイスカレー小 | AD15: 800 | AF15: カレーがなくなり次第終了 | AG15: 激辛スパイスカレー 4辛 | AH15: 4辛のスパイスカレー食べ切ったら、次回スパイスカレー400円引き | AI15: 1250 | AK15: 激辛です。お子様のチャレンジは出来ません。 | AL15: 5 | AM15: {=_xlfn.XLOOKUP($B15,'シート1'!$B$2:$B$70,'シート1'!$A$2:$A$70,"",0,1)} -> 45 | AN15: {=_xlfn.XLOOKUP($B15,'シート1'!$B$2:$B$70,'シート1'!C$2:C$70,"",0,1)} -> デートの行き先、カレー屋 | AO15: {=_xlfn.XLOOKUP($B15,'シート1'!$B$2:$B$70,'シート1'!D$2:D$70,"",0,1)} -> https://www.instagram.com/sheandcurry | AP15: {=_xlfn.XLOOKUP($B15,'シート1'!$B$2:$B$70,'シート1'!E$2:E$70,"",0,1)} -> 大阪市大正区泉尾１丁目３０−１５ 平本ビル | AQ15: {=_xlfn.XLOOKUP($B15,'シート1'!$B$2:$B$70,'シート1'!F$2:F$70,"",0,1)} | AR15: 46417
A16: 46305.673 | B16: B.B.QホルモンＭＯＵ | C16: 参加する | D16: 三軒家東 | E16: 焼肉・ホルモン | F16: 立ち飲み | G16: サク飲み | H16: テイクアウトOK | I16: 日曜日, 月曜日, 水曜日, 木曜日, 金曜日, 土曜日 | J16: 0.70833333 | K16: 0.89583333 | M16: 現金 | N16: いいえ、希望しません。 | O16: 「酔いどれセット」のみで参加 | P16: 酔いどれセット | Q16: ホルモンとドリンク | S16: 700 | AL16: 10 | AM16: {=_xlfn.XLOOKUP($B16,'シート1'!$B$2:$B$70,'シート1'!$A$2:$A$70,"",0,1)} -> 34 | AN16: {=_xlfn.XLOOKUP($B16,'シート1'!$B$2:$B$70,'シート1'!C$2:C$70,"",0,1)} -> 立ち飲み・ホルモン | AO16: {=_xlfn.XLOOKUP($B16,'シート1'!$B$2:$B$70,'シート1'!D$2:D$70,"",0,1)} -> https://www.instagram.com/bbq.mou.29 | AP16: {=_xlfn.XLOOKUP($B16,'シート1'!$B$2:$B$70,'シート1'!E$2:E$70,"",0,1)} -> 大阪市大正区三軒家東１丁目２−４ | AQ16: {=_xlfn.XLOOKUP($B16,'シート1'!$B$2:$B$70,'シート1'!F$2:F$70,"",0,1)} -> https://maps.app.goo.gl/kCXY14AkjvY7xeAX8
A17: 46305.716 | B17: 呑め屋 集合！ | C17: 参加する | D17: 泉尾 | E17: 居酒屋 | F17: テーブルあり | G17: 腹ごしらえ | H17: テイクアウトOK | I17: 日曜日, 月曜日, 金曜日, 土曜日 | J17: 0.77083333 | K17: 0.91666667 | M17: 現金 | N17: はい。希望します。 | O17: 「酔いどれセット」・「店舗クエスト」両方で参加 | AA17: 集合セット | AB17: ドリンク1杯＋日替わりメニュー1品 | AD17: 500 | AG17: あみだくじ | AH17: 罰ゲームもありのあみだくじ | AI17: 500 | AL17: 10 | AM17: {=_xlfn.XLOOKUP($B17,'シート1'!$B$2:$B$70,'シート1'!$A$2:$A$70,"",0,1)} -> 46 | AN17: {=_xlfn.XLOOKUP($B17,'シート1'!$B$2:$B$70,'シート1'!C$2:C$70,"",0,1)} -> 素朴な家庭料理 | AO17: {=_xlfn.XLOOKUP($B17,'シート1'!$B$2:$B$70,'シート1'!D$2:D$70,"",0,1)} -> https://www.instagram.com/syuugo_ma_0418 | AP17: {=_xlfn.XLOOKUP($B17,'シート1'!$B$2:$B$70,'シート1'!E$2:E$70,"",0,1)} -> 大阪市大正区泉尾5丁目２－２ | AQ17: {=_xlfn.XLOOKUP($B17,'シート1'!$B$2:$B$70,'シート1'!F$2:F$70,"",0,1)}
A18: 46305.735 | B18: いっぱい呑み 花 | C18: 参加する | D18: 千島 | E18: 居酒屋 | F18: カウンター | G18: サク飲み | H18: テイクアウトOK | I18: 日曜日, 火曜日, 水曜日, 木曜日, 金曜日, 土曜日 | J18: 0.70833333 | K18: 0.875 | M18: 現金, paypay | N18: いいえ、希望しません。 | O18: 「酔いどれセット」・「店舗クエスト」両方で参加 | AA18: せんべろ | AB18: 生ビールか500円以下のワンドリンクとおでんのスジ以外3品かおばんざい1品 | AD18: 1000 | AG18: じゃんけんクエスト | AH18: ワンドリンクを賭けて勝負！ジャンケンして勝てば無料、あいこなら半額、負けたらスタッフにドリンク1杯！ | AI18: 100 | AL18: 10 | AM18: {=_xlfn.XLOOKUP($B18,'シート1'!$B$2:$B$70,'シート1'!$A$2:$A$70,"",0,1)} -> 58 | AN18: {=_xlfn.XLOOKUP($B18,'シート1'!$B$2:$B$70,'シート1'!C$2:C$70,"",0,1)} -> おひとり様でもふらっと気軽に | AO18: {=_xlfn.XLOOKUP($B18,'シート1'!$B$2:$B$70,'シート1'!D$2:D$70,"",0,1)} -> https://www.instagram.com/ippainomi.hana0806 | AP18: {=_xlfn.XLOOKUP($B18,'シート1'!$B$2:$B$70,'シート1'!E$2:E$70,"",0,1)} -> 大阪市大正区千島3丁目4-7 | AQ18: {=_xlfn.XLOOKUP($B18,'シート1'!$B$2:$B$70,'シート1'!F$2:F$70,"",0,1)} -> https://maps.app.goo.gl/qxCPY32XRzxQ52ni7
A19: 46305.855 | B19: SNACK 2軒め の〜てんき | C19: 参加する | D19: 駅前 | E19: スナック | F19: カウンター | G19: 夜遊び | H19: テイクアウト不可 | I19: 月曜日, 火曜日, 水曜日, 木曜日, 金曜日, 土曜日 | J19: 0.83333333 | K19: 0.95833333 | M19: 現金, paypay, クレジットカード | N19: いいえ、希望しません。 | O19: 「店舗クエスト」のみで参加 | V19: サクッと呑み | W19: セット半額 | X19: 男性2000円 女性1500円 | Y19: ワンドリンク込み | AL19: 2 | AM19: {=_xlfn.XLOOKUP($B19,'シート1'!$B$2:$B$70,'シート1'!$A$2:$A$70,"",0,1)} -> 38 | AN19: {=_xlfn.XLOOKUP($B19,'シート1'!$B$2:$B$70,'シート1'!C$2:C$70,"",0,1)} -> 楽しく呑めて歌える憩いの場 | AO19: {=_xlfn.XLOOKUP($B19,'シート1'!$B$2:$B$70,'シート1'!D$2:D$70,"",0,1)} -> https://www.instagram.com/__2knme0703 | AP19: {=_xlfn.XLOOKUP($B19,'シート1'!$B$2:$B$70,'シート1'!E$2:E$70,"",0,1)} -> 大阪市大正区三軒家西１丁目４−１６ベルコモンズ大正 | AQ19: {=_xlfn.XLOOKUP($B19,'シート1'!$B$2:$B$70,'シート1'!F$2:F$70,"",0,1)}
A20: 46306.812 | B20: ふじわら君 | C20: 参加しない | AM20: {=_xlfn.XLOOKUP($B20,'シート1'!$B$2:$B$70,'シート1'!$A$2:$A$70,"",0,1)} -> 10 | AN20: {=_xlfn.XLOOKUP($B20,'シート1'!$B$2:$B$70,'シート1'!C$2:C$70,"",0,1)} -> 創作料理居酒屋 | AO20: {=_xlfn.XLOOKUP($B20,'シート1'!$B$2:$B$70,'シート1'!D$2:D$70,"",0,1)} -> https://www.instagram.com/fujiwarakun_taisho | AP20: {=_xlfn.XLOOKUP($B20,'シート1'!$B$2:$B$70,'シート1'!E$2:E$70,"",0,1)} -> 大阪市大正区三軒家西１丁目１−７ | AQ20: {=_xlfn.XLOOKUP($B20,'シート1'!$B$2:$B$70,'シート1'!F$2:F$70,"",0,1)} -> https://maps.app.goo.gl/svhsvpjHHy4Wfxv49
A21: 46309.794 | B21: 鉄板焼き栄八大阪大正店 | C21: 参加する | D21: 駅前 | E21: 串焼き・鉄板焼き | F21: テーブルあり | G21: 腹ごしらえ | H21: テイクアウトOK | I21: 日曜日, 金曜日, 土曜日 | J21: 0.70833333 | K21: 0.91666667 | M21: 現金 | N21: いいえ、希望しません。 | O21: 「酔いどれセット」のみで参加 | P21: 鉄板焼2種盛合せ | Q21: 鉄板焼おつまみ2種 | R21: 仕入状況により内容変わりますので詳しくは記載せずにいます | S21: 1000 | T21: なし | U21: なし | AL21: 5 | AM21: {=_xlfn.XLOOKUP($B21,'シート1'!$B$2:$B$70,'シート1'!$A$2:$A$70,"",0,1)} -> 21 | AN21: {=_xlfn.XLOOKUP($B21,'シート1'!$B$2:$B$70,'シート1'!C$2:C$70,"",0,1)} -> お好み・焼きそば・鉄板居酒屋 | AO21: {=_xlfn.XLOOKUP($B21,'シート1'!$B$2:$B$70,'シート1'!D$2:D$70,"",0,1)} -> https://www.instagram.com/teppanyaki_eihachi | AP21: {=_xlfn.XLOOKUP($B21,'シート1'!$B$2:$B$70,'シート1'!E$2:E$70,"",0,1)} -> 大阪市大正区三軒家西１丁目６−３ | AQ21: {=_xlfn.XLOOKUP($B21,'シート1'!$B$2:$B$70,'シート1'!F$2:F$70,"",0,1)} -> https://maps.app.goo.gl/SgdnoFYhwHF52vjd8
A22: 46310.974 | B22: TM’s DINER | C22: 参加する | D22: 三軒家東 | E22: 多国籍料理 | F22: テーブルあり | G22: サク飲み | H22: テイクアウトOK | I22: 日曜日, 月曜日, 火曜日, 金曜日, 土曜日 | J22: 0.47916667 | K22: 0 | L22: ディナーは30分前ラストオーダーなのでそれまでにご来店をお願いします。 | M22: 現金, paypay, クレジットカード, d払い、auペイ、楽天ペイ、メルペイ、などなど | N22: はい。希望します。 | O22: 「酔いどれセット」のみで参加 | P22: TM's酔いどれセット | Q22: イベント限定メニュー+1ドリンク | S22: 1000 | U22: 30 | AL22: 10 | AM22: {=_xlfn.XLOOKUP($B22,'シート1'!$B$2:$B$70,'シート1'!$A$2:$A$70,"",0,1)} -> 32 | AN22: {=_xlfn.XLOOKUP($B22,'シート1'!$B$2:$B$70,'シート1'!C$2:C$70,"",0,1)} -> イタリアン・メキシカン・アメリカン | AO22: {=_xlfn.XLOOKUP($B22,'シート1'!$B$2:$B$70,'シート1'!D$2:D$70,"",0,1)} -> https://www.instagram.com/tms_diner_osaka | AP22: {=_xlfn.XLOOKUP($B22,'シート1'!$B$2:$B$70,'シート1'!E$2:E$70,"",0,1)} -> 大阪市大正区三軒家東１丁目２−５ 2F | AQ22: {=_xlfn.XLOOKUP($B22,'シート1'!$B$2:$B$70,'シート1'!F$2:F$70,"",0,1)} -> https://maps.app.goo.gl/qM8P7SU6UqcARZm29
A23: 46312.586 | B23: 3PIECE | C23: 参加する | D23: 南恩加島 | E23: BAR | F23: テーブルあり | G23: 夜遊び | H23: テイクアウト不可 | I23: 火曜日, 水曜日, 木曜日, 金曜日, 土曜日 | J23: 0.79166667 | K23: 0 | L23: 金曜、土曜力尽きるまで | M23: 現金, paypay, クレジットカード | N23: はい。希望します。 | O23: 「店舗クエスト」のみで参加 | V23: カラオケで高得点！ | W23: 93点以上だした方は指定ドリンク一杯無料 | X23: 100 | Y23: ？ | AL23: 10 | AM23: {=_xlfn.XLOOKUP($B23,'シート1'!$B$2:$B$70,'シート1'!$A$2:$A$70,"",0,1)} -> 53 | AN23: {=_xlfn.XLOOKUP($B23,'シート1'!$B$2:$B$70,'シート1'!C$2:C$70,"",0,1)} -> アットホームなカラオケBAR | AO23: {=_xlfn.XLOOKUP($B23,'シート1'!$B$2:$B$70,'シート1'!D$2:D$70,"",0,1)} -> https://www.instagram.com/3piece_osake | AP23: {=_xlfn.XLOOKUP($B23,'シート1'!$B$2:$B$70,'シート1'!E$2:E$70,"",0,1)} -> 大阪市大正区南恩加島６丁目７−８ | AQ23: {=_xlfn.XLOOKUP($B23,'シート1'!$B$2:$B$70,'シート1'!F$2:F$70,"",0,1)} -> https://maps.app.goo.gl/67gvLqPdoESWNqod7
A24: 46315.688 | B24: だしと鶏ちゃぼ大正店 | C24: 参加する | D24: 駅前 | E24: 鶏料理 | F24: テーブルあり | G24: 腹ごしらえ | H24: テイクアウト不可 | I24: 月曜日, 火曜日, 水曜日, 木曜日 | J24: 0.72916667 | K24: 0.95833333 | M24: 現金, クレジットカード | N24: いいえ、希望しません。 | O24: 「酔いどれセット」のみで参加 | P24: 酔いどれセット | Q24: ドリンク1杯、肉豆腐、国産鶏の出汁煮2本 | R24: ドリンクは瓶ビール、日本酒を除く | S24: 1100 | T24: なし | U24: なし | AL24: 10 | AM24: {=_xlfn.XLOOKUP($B24,'シート1'!$B$2:$B$70,'シート1'!$A$2:$A$70,"",0,1)} -> 9 | AN24: {=_xlfn.XLOOKUP($B24,'シート1'!$B$2:$B$70,'シート1'!C$2:C$70,"",0,1)} -> 焼き鳥・お出汁料理 | AO24: {=_xlfn.XLOOKUP($B24,'シート1'!$B$2:$B$70,'シート1'!D$2:D$70,"",0,1)} -> https://www.instagram.com/chabo_taisho | AP24: {=_xlfn.XLOOKUP($B24,'シート1'!$B$2:$B$70,'シート1'!E$2:E$70,"",0,1)} -> 大阪市大正区三軒家東１丁目１７−１６ | AQ24: {=_xlfn.XLOOKUP($B24,'シート1'!$B$2:$B$70,'シート1'!F$2:F$70,"",0,1)} -> https://maps.app.goo.gl/a9AcRcjV9q895Jeo6
A25: 46315.721 | B25: 鉄板焼き ぷれこ | C25: 参加する | D25: 泉尾 | E25: 鉄板焼・焼きそば | F25: テーブルあり | G25: 腹ごしらえ | H25: テイクアウト不可 | I25: 月曜日, 火曜日, 水曜日, 木曜日, 金曜日, 土曜日 | J25: 0.70833333 | K25: 0.41666667 | M25: 現金, paypay, クレジットカード | N25: はい。希望します。 | O25: 「酔いどれセット」・「店舗クエスト」両方で参加 | AA25: とん平＆ドリンク | AB25: とん平とドリンク(生・酎ハイ・ハイボール) | AD25: 1000 | AE25: 0 | AF25: 限定なし | AL25: 10 | AM25: {=_xlfn.XLOOKUP($B25,'シート1'!$B$2:$B$70,'シート1'!$A$2:$A$70,"",0,1)} -> 44 | AN25: {=_xlfn.XLOOKUP($B25,'シート1'!$B$2:$B$70,'シート1'!C$2:C$70,"",0,1)} -> 変態植物倶楽部の店 | AO25: {=_xlfn.XLOOKUP($B25,'シート1'!$B$2:$B$70,'シート1'!D$2:D$70,"",0,1)} -> https://www.instagram.com/pureko.yakisoba___ | AP25: {=_xlfn.XLOOKUP($B25,'シート1'!$B$2:$B$70,'シート1'!E$2:E$70,"",0,1)} -> 大阪市大正区泉尾１丁目２２−１２ | AQ25: {=_xlfn.XLOOKUP($B25,'シート1'!$B$2:$B$70,'シート1'!F$2:F$70,"",0,1)} -> https://maps.app.goo.gl/7LxwLtzxhZXxzxw59
A26: 46315.926 | B26: BAR EDIT | C26: 参加する | D26: 泉尾 | E26: BAR | F26: カウンター | G26: ひと休み | H26: テイクアウト不可 | I26: 日曜日, 月曜日, 火曜日, 水曜日, 金曜日, 土曜日 | J26: 0.79166667 | K26: 0.083333333 | L26: 01:30ラストオーダー | M26: 現金 | N26: いいえ、希望しません。 | O26: 「酔いどれセット」のみで参加 | P26: EDIT酔いどれセット | Q26: お酒orソフトドリンク＋チャーム | R26: こちらでよいどれクエスト用のメニューを作って選んでもらいます。 | S26: 1000 | AL26: 5 | AM26: {=_xlfn.XLOOKUP($B26,'シート1'!$B$2:$B$70,'シート1'!$A$2:$A$70,"",0,1)} -> 40 | AN26: {=_xlfn.XLOOKUP($B26,'シート1'!$B$2:$B$70,'シート1'!C$2:C$70,"",0,1)} -> お酒&カルチャー発信場所 | AO26: {=_xlfn.XLOOKUP($B26,'シート1'!$B$2:$B$70,'シート1'!D$2:D$70,"",0,1)} -> https://www.instagram.com/bar_edit_osaka | AP26: {=_xlfn.XLOOKUP($B26,'シート1'!$B$2:$B$70,'シート1'!E$2:E$70,"",0,1)} -> 大阪市大正区泉尾１丁目３０−１５ 平本ビル | AQ26: {=_xlfn.XLOOKUP($B26,'シート1'!$B$2:$B$70,'シート1'!F$2:F$70,"",0,1)} -> https://maps.app.goo.gl/o8GMyay7XvnYpEwk7
A27: 46317.31 | B27: Pizzeria Legare | C27: 参加する | D27: 平尾 | E27: イタリアン | F27: テーブルあり | G27: 腹ごしらえ | H27: テイクアウト不可 | I27: 月曜日, 火曜日, 水曜日, 木曜日, 金曜日, 土曜日 | J27: 0.70833333 | K27: 0.875 | M27: 現金, paypay, クレジットカード | N27: いいえ、希望しません。 | O27: 「酔いどれセット」のみで参加 | P27: legare酔いどれセット | Q27: その日の前菜盛り合わせ➕ドリンク | R27: 生ビール、酎ハイ、ハイボール、ドイツワイン(グラス)からお選びください | S27: 1000 | T27: なし | U27: 限定10セット／日 | AL27: 10 | AM27: {=_xlfn.XLOOKUP($B27,'シート1'!$B$2:$B$70,'シート1'!$A$2:$A$70,"",0,1)} -> 33 | AN27: {=_xlfn.XLOOKUP($B27,'シート1'!$B$2:$B$70,'シート1'!C$2:C$70,"",0,1)} -> 本格ピッツァ・ドイツワイン | AO27: {=_xlfn.XLOOKUP($B27,'シート1'!$B$2:$B$70,'シート1'!D$2:D$70,"",0,1)} -> https://www.instagram.com/pizzerialegare | AP27: {=_xlfn.XLOOKUP($B27,'シート1'!$B$2:$B$70,'シート1'!E$2:E$70,"",0,1)} -> 大阪市大正区平尾５丁目１２−１６ | AQ27: {=_xlfn.XLOOKUP($B27,'シート1'!$B$2:$B$70,'シート1'!F$2:F$70,"",0,1)} -> https://maps.app.goo.gl/e85zQpDRWme5xsyr6
A28: 46317.749 | B28: 福人(ふくんちゅ) | C28: 参加する | D28: 三軒家東 | E28: 沖縄料理 | F28: テーブルあり | G28: 腹ごしらえ | H28: テイクアウトOK | I28: 全て | J28: 0.70833333 | K28: 0.95833333 | M28: 現金, paypay, クレジットカード | N28: いいえ、希望しません。 | O28: 「酔いどれセット」のみで参加 | P28: 福人セット | Q28: 豚バラ軟骨塩煮込み+ゴーヤおひたし＋ドリンク1杯 | S28: 1000 | AL28: 5 | AM28: {=_xlfn.XLOOKUP($B28,'シート1'!$B$2:$B$70,'シート1'!$A$2:$A$70,"",0,1)} -> 31 | AN28: {=_xlfn.XLOOKUP($B28,'シート1'!$B$2:$B$70,'シート1'!C$2:C$70,"",0,1)} -> 作りたいもん作りまっせ居酒屋 | AO28: {=_xlfn.XLOOKUP($B28,'シート1'!$B$2:$B$70,'シート1'!D$2:D$70,"",0,1)} -> https://www.instagram.com/fuku__nchu | AP28: {=_xlfn.XLOOKUP($B28,'シート1'!$B$2:$B$70,'シート1'!E$2:E$70,"",0,1)} -> 大阪市大正区三軒家東１丁目１６−２６ | AQ28: {=_xlfn.XLOOKUP($B28,'シート1'!$B$2:$B$70,'シート1'!F$2:F$70,"",0,1)} -> https://maps.app.goo.gl/PB2QxJm3seTe8PFH6
A29: 46319.578 | B29: Neboke-ネボケ | C29: 参加する | D29: 駅前 | E29: BAR | F29: テーブルあり | G29: ひと休み | H29: テイクアウト不可 | I29: 全て | J29: 0.79166667 | K29: 0.125 | M29: 現金, paypay, クレジットカード | N29: いいえ、希望しません。 | O29: 「酔いどれセット」・「店舗クエスト」両方で参加 | AA29: 冒険者の休息 | AB29: ドリンク+おつまみ | AC29: 1000円までのドリンク+おつまみ、またはおつまみがいらない場合は1400円までのドリンク | AD29: 1000 | AE29: 660 | AG29: 洞窟探検 | AH29: くじを引いてモンスターの絵なら次回以降チャージ無料券、お金の絵なら今日のチャージ無料 | AI29: 0 | AJ29: 0 | AL29: 10 | AM29: {=_xlfn.XLOOKUP($B29,'シート1'!$B$2:$B$70,'シート1'!$A$2:$A$70,"",0,1)} -> 17 | AN29: {=_xlfn.XLOOKUP($B29,'シート1'!$B$2:$B$70,'シート1'!C$2:C$70,"",0,1)} -> 隠れ家バー | AO29: {=_xlfn.XLOOKUP($B29,'シート1'!$B$2:$B$70,'シート1'!D$2:D$70,"",0,1)} -> https://www.instagram.com/Neboke_bar | AP29: {=_xlfn.XLOOKUP($B29,'シート1'!$B$2:$B$70,'シート1'!E$2:E$70,"",0,1)} -> 大阪市大正区三軒家西１丁目５−７ | AQ29: {=_xlfn.XLOOKUP($B29,'シート1'!$B$2:$B$70,'シート1'!F$2:F$70,"",0,1)} -> https://maps.app.goo.gl/WiS8rFbF993DeBHp9
A30: 46320.74 | B30: ザ·沖縄 | C30: 参加する | D30: 三軒家東 | E30: 居酒屋 | F30: テーブルあり | G30: 夜遊び | H30: テイクアウト不可 | I30: 全て | J30: 0.79166667 | K30: 0.083333333 | M30: 現金 | N30: はい。希望します。 | O30: 「酔いどれセット」のみで参加 | P30: 1ドリンクと付き出しとお菓子 | Q30: 1ドリンクと付き出しとお菓子 | S30: 1000 | T30: 0 | U30: 制限無 | AL30: 10 | AM30: {=_xlfn.XLOOKUP($B30,'シート1'!$B$2:$B$70,'シート1'!$A$2:$A$70,"",0,1)} -> 28 | AN30: {=_xlfn.XLOOKUP($B30,'シート1'!$B$2:$B$70,'シート1'!C$2:C$70,"",0,1)} -> 沖縄料理・カラオケ居酒屋 | AO30: {=_xlfn.XLOOKUP($B30,'シート1'!$B$2:$B$70,'シート1'!D$2:D$70,"",0,1)} -> https://www.instagram.com/za.okinawa | AP30: {=_xlfn.XLOOKUP($B30,'シート1'!$B$2:$B$70,'シート1'!E$2:E$70,"",0,1)} -> 大阪市大正区三軒家東１丁目５−１０ | AQ30: {=_xlfn.XLOOKUP($B30,'シート1'!$B$2:$B$70,'シート1'!F$2:F$70,"",0,1)} -> https://maps.app.goo.gl/Prnu5oBX6hyQzpft6
A31: 46320.84 | B31: たこ焼き･お好み焼き そーすや | C31: 参加する | D31: 鶴町 | E31: たこ焼き・お好み焼き | F31: テーブルあり | G31: 腹ごしらえ | H31: テイクアウトOK | I31: 日曜日, 土曜日 | J31: 0.45833333 | K31: 0.83333333 | L31: 土曜の営業は17時～ 日曜の営業は11時～ | M31: 現金 | N31: はい。希望します。 | O31: 「酔いどれセット」のみで参加 | P31: 酔いどれセット | Q31: アルコール類1杯+おでん3種盛り | R31: おでん（大根、厚揚げ、こんにゃく、たまご、ちくわ、ごぼ天、はんぺん、じゃがいもの中から3品) | S31: 500 | T31: 0 | U31: 無くなりしだい終了 | AL31: 10 | AM31: {=_xlfn.XLOOKUP($B31,'シート1'!$B$2:$B$70,'シート1'!$A$2:$A$70,"",0,1)} -> 54 | AN31: {=_xlfn.XLOOKUP($B31,'シート1'!$B$2:$B$70,'シート1'!C$2:C$70,"",0,1)} -> 一品もあって呑める店 | AO31: {=_xlfn.XLOOKUP($B31,'シート1'!$B$2:$B$70,'シート1'!D$2:D$70,"",0,1)} -> https://www.instagram.com/so__suya | AP31: {=_xlfn.XLOOKUP($B31,'シート1'!$B$2:$B$70,'シート1'!E$2:E$70,"",0,1)} -> 大阪市大正区鶴町３丁目９−８ | AQ31: {=_xlfn.XLOOKUP($B31,'シート1'!$B$2:$B$70,'シート1'!F$2:F$70,"",0,1)} -> https://maps.app.goo.gl/xJwhZ9ZwW7z19PcK6
A32: 46321.734 | B32: 酒と魚 喰海~KUKAI~ | C32: 参加する | D32: 千島 | E32: 居酒屋 | F32: テーブルあり | G32: サク飲み | H32: テイクアウト不可 | I32: 全て | J32: 0.66666667 | K32: 0.95833333 | L32: 混み具合により遅れる可能性有り | M32: 現金 | N32: いいえ、希望しません。 | O32: 「酔いどれセット」のみで参加 | P32: 変なお魚あるかも？ | Q32: 三種盛り＋ドリンク1杯 | R32: 瓶ビール、日本酒、一部ドリンクは対象外 | S32: 1000 | T32: 0 | U32: 仕入れにより変動有り | AL32: 5 | AM32: {=_xlfn.XLOOKUP($B32,'シート1'!$B$2:$B$70,'シート1'!$A$2:$A$70,"",0,1)} -> 49 | AN32: {=_xlfn.XLOOKUP($B32,'シート1'!$B$2:$B$70,'シート1'!C$2:C$70,"",0,1)} -> 安くて美味い変な魚屋さん | AO32: {=_xlfn.XLOOKUP($B32,'シート1'!$B$2:$B$70,'シート1'!D$2:D$70,"",0,1)} -> https://www.instagram.com/kukai_izakaya_ | AP32: {=_xlfn.XLOOKUP($B32,'シート1'!$B$2:$B$70,'シート1'!E$2:E$70,"",0,1)} -> 大阪市大正区千島３丁目３−１２ シティハイツ大正 | AQ32: {=_xlfn.XLOOKUP($B32,'シート1'!$B$2:$B$70,'シート1'!F$2:F$70,"",0,1)} -> https://maps.app.goo.gl/2SUDVhYEkfnGQu8q9
A33: 46321.846 | B33: クラスノ | C33: 参加する | D33: 三軒家西 | E33: 居酒屋 | F33: テーブルあり | G33: 腹ごしらえ | H33: テイクアウトOK | I33: 月曜日, 火曜日, 水曜日, 木曜日, 金曜日 | J33: 0.66666667 | K33: 0.91666667 | M33: 現金 | N33: はい。希望します。 | O33: 「酔いどれセット」のみで参加 | P33: クラスノ酔どれ | Q33: くわ焼き1品【2本】ドリンク一杯【瓶、日本酒以外】鮪の煮付け【小】えんどうの煮付け【小】 | R33: お酒とくわ焼きの組み合わせにより、千円に満たない場合は、お釣りを返金致します | S33: 1000 | U33: 限定20セット | AL33: 10 | AM33: {=_xlfn.XLOOKUP($B33,'シート1'!$B$2:$B$70,'シート1'!$A$2:$A$70,"",0,1)} -> 57 | AN33: {=_xlfn.XLOOKUP($B33,'シート1'!$B$2:$B$70,'シート1'!C$2:C$70,"",0,1)} -> 1949年創業の老舗酒場 | AO33: {=_xlfn.XLOOKUP($B33,'シート1'!$B$2:$B$70,'シート1'!D$2:D$70,"",0,1)} -> https://www.instagram.com/kurasuno0.2 | AP33: {=_xlfn.XLOOKUP($B33,'シート1'!$B$2:$B$70,'シート1'!E$2:E$70,"",0,1)} -> 大阪市大正区三軒家東１丁目３−１１ | AQ33: {=_xlfn.XLOOKUP($B33,'シート1'!$B$2:$B$70,'シート1'!F$2:F$70,"",0,1)} -> https://maps.app.goo.gl/LGRvgFisDgQDWBtZ9
A34: 46322.651 | B34: NONA | C34: 参加する | D34: 泉尾 | E34: カフェ | F34: カウンター | G34: ひと休み | H34: テイクアウトOK | I34: 木曜日, 金曜日, 土曜日 | J34: 0.41666667 | K34: 0.70833333 | L34: ドーナツ提供時間、1つにつき4分かかります | M34: 現金, paypay, クレジットカード | N34: いいえ、希望しません。 | O34: 「酔いどれセット」のみで参加 | P34: ドーナツセット | Q34: プレーンドーナツと400円までのコーヒー、ソフトドリンク1杯 | R34: 400円以上のドリンク、またはアルコール類は差額頂ければ提供可能 | S34: 600 | U34: 10 | AL34: 10 | AM34: {=_xlfn.XLOOKUP($B34,'シート1'!$B$2:$B$70,'シート1'!$A$2:$A$70,"",0,1)} -> 35 | AN34: {=_xlfn.XLOOKUP($B34,'シート1'!$B$2:$B$70,'シート1'!C$2:C$70,"",0,1)} -> ホットサンド・カフェバー | AO34: {=_xlfn.XLOOKUP($B34,'シート1'!$B$2:$B$70,'シート1'!D$2:D$70,"",0,1)} -> https://www.instagram.com/cafe.bar.nona9 | AP34: {=_xlfn.XLOOKUP($B34,'シート1'!$B$2:$B$70,'シート1'!E$2:E$70,"",0,1)} -> 大阪市大正区泉尾２丁目１１−９ | AQ34: {=_xlfn.XLOOKUP($B34,'シート1'!$B$2:$B$70,'シート1'!F$2:F$70,"",0,1)} -> https://maps.app.goo.gl/hsSrRGzYZdxe5zo27
A35: 46322.657 | B35: BAR K'S〜ケーズ〜 | C35: 参加する | D35: 三軒家西 | E35: BAR | F35: カウンター | G35: 夜遊び | H35: テイクアウト不可 | I35: 日曜日, 月曜日, 火曜日, 木曜日, 金曜日, 土曜日 | J35: 0.83333333 | K35: 0.20833333 | M35: 現金, paypay, クレジットカード, d払い,auペイ | N35: いいえ、希望しません。 | O35: 「酔いどれセット」・「店舗クエスト」両方で参加 | AA35: 限定カクテル (飲み放題 1h ) | AB35: 酔いどれ参加者のみが注文できるカクテル | AD35: 男性2200円女性1650円 | AE35: なし | AG35: ダーツクエスト | AH35: ダーツ3本投げて60点以上でテキーラサービス(１杯) | AI35: なし | AJ35: なし | AL35: 10 | AM35: {=_xlfn.XLOOKUP($B35,'シート1'!$B$2:$B$70,'シート1'!$A$2:$A$70,"",0,1)} -> 7 | AN35: {=_xlfn.XLOOKUP($B35,'シート1'!$B$2:$B$70,'シート1'!C$2:C$70,"",0,1)} -> ダーツ・カラオケ | AO35: {=_xlfn.XLOOKUP($B35,'シート1'!$B$2:$B$70,'シート1'!D$2:D$70,"",0,1)} -> https://www.instagram.com/bar_ks_taisho | AP35: {=_xlfn.XLOOKUP($B35,'シート1'!$B$2:$B$70,'シート1'!E$2:E$70,"",0,1)} -> 大阪市大正区三軒家西１丁目４−１６ベルコモンズ大正2D | AQ35: {=_xlfn.XLOOKUP($B35,'シート1'!$B$2:$B$70,'シート1'!F$2:F$70,"",0,1)} -> https://maps.app.goo.gl/h1iC1PzMoU3TmyDg9
A36: 46322.929 | B36: 焼肉ホルモンたろちゃん大正橋店 | C36: 参加する | D36: 駅前 | E36: 居酒屋 | F36: カウンター | G36: サク飲み | H36: テイクアウト不可 | I36: 日曜日, 月曜日, 火曜日, 木曜日, 金曜日, 土曜日 | J36: 0.45833333 | K36: 0.89583333 | M36: 現金 | N36: いいえ、希望しません。 | O36: 「酔いどれセット」のみで参加 | P36: お得！たろちゃんセット | Q36: 1ドリンク➕あて2品盛り | R36: ドリンク390円以内！ | S36: 500 | AL36: 5 | AM36: {=_xlfn.XLOOKUP($B36,'シート1'!$B$2:$B$70,'シート1'!$A$2:$A$70,"",0,1)} -> 20 | AN36: {=_xlfn.XLOOKUP($B36,'シート1'!$B$2:$B$70,'シート1'!C$2:C$70,"",0,1)} -> 駅前で昼から飲める店 | AO36: {=_xlfn.XLOOKUP($B36,'シート1'!$B$2:$B$70,'シート1'!D$2:D$70,"",0,1)} -> https://www.instagram.com/tarochan_taisho | AP36: {=_xlfn.XLOOKUP($B36,'シート1'!$B$2:$B$70,'シート1'!E$2:E$70,"",0,1)} -> 大阪市大正区三軒家東１丁目２−６ | AQ36: {=_xlfn.XLOOKUP($B36,'シート1'!$B$2:$B$70,'シート1'!F$2:F$70,"",0,1)} -> https://maps.app.goo.gl/P1ytbeyLANs4TgD19
A37: 46323.519 | B37: 大正焼肉 ホルモン焼みやけ | C37: 参加する | D37: 三軒家東 | E37: 焼肉・ホルモン | F37: テーブルあり | G37: 腹ごしらえ | H37: テイクアウト不可 | I37: 全て | J37: 0.70833333 | K37: 0.91666667 | M37: 現金, paypay, クレジットカード | N37: いいえ、希望しません。 | O37: 「酔いどれセット」のみで参加 | P37: ホロ酔いセット | Q37: ホルモン盛り合わせ150g+ドリンク1杯 | S37: 1500 | AL37: 0 | AM37: {=_xlfn.XLOOKUP($B37,'シート1'!$B$2:$B$70,'シート1'!$A$2:$A$70,"",0,1)} -> 48 | AN37: {=_xlfn.XLOOKUP($B37,'シート1'!$B$2:$B$70,'シート1'!C$2:C$70,"",0,1)} -> 国産牛新鮮ホルモン焼 | AO37: {=_xlfn.XLOOKUP($B37,'シート1'!$B$2:$B$70,'シート1'!D$2:D$70,"",0,1)} -> https://www.instagram.com/horumonyaki_miyake | AP37: {=_xlfn.XLOOKUP($B37,'シート1'!$B$2:$B$70,'シート1'!E$2:E$70,"",0,1)} -> 大阪市大正区三軒家東１丁目１０−２２ 1階 | AQ37: {=_xlfn.XLOOKUP($B37,'シート1'!$B$2:$B$70,'シート1'!F$2:F$70,"",0,1)} -> https://maps.app.goo.gl/vtyUhfcTtNvREszDA
A38: 46323.664 | B38: Zakky's ホットドッグ | C38: 参加する | D38: 千島 | E38: ホットドッグ | F38: テーブルあり | G38: サク飲み | H38: テイクアウトOK | I38: 日曜日, 月曜日, 火曜日, 水曜日, 木曜日, 土曜日 | J38: 0.33333333 | K38: 0.70833333 | M38: 現金, paypay | N38: いいえ、希望しません。 | O38: 「酔いどれセット」のみで参加 | P38: ミニザッキーズセット | Q38: 生ビールとミニビーフドッグorミニホットドッグ | S38: 1000 | T38: 0 | U38: 限定30セット／日 | AL38: 10 | AM38: {=_xlfn.XLOOKUP($B38,'シート1'!$B$2:$B$70,'シート1'!$A$2:$A$70,"",0,1)} -> 50 | AN38: {=_xlfn.XLOOKUP($B38,'シート1'!$B$2:$B$70,'シート1'!C$2:C$70,"",0,1)} -> 大正アメリンカンダイナー | AO38: {=_xlfn.XLOOKUP($B38,'シート1'!$B$2:$B$70,'シート1'!D$2:D$70,"",0,1)} -> https://www.instagram.com/zakkys_hotdog | AP38: {=_xlfn.XLOOKUP($B38,'シート1'!$B$2:$B$70,'シート1'!E$2:E$70,"",0,1)} -> 大阪市大正区千島３丁目１２−１３ ハイグレード千島 | AQ38: {=_xlfn.XLOOKUP($B38,'シート1'!$B$2:$B$70,'シート1'!F$2:F$70,"",0,1)} -> https://maps.app.goo.gl/UVjYbt57Dy43WcJN9
A39: 46324.029 | B39: 和んでや | C39: 参加する | D39: 三軒家東 | E39: おばんざい | F39: カウンター | G39: ひと休み | H39: テイクアウト不可 | I39: 金曜日, 土曜日 | J39: 0.79166667 | K39: 0 | L39: ママのHP次第で24時以降も営業してるパターン有り | M39: 現金 | N39: はい。希望します。 | O39: 「酔いどれセット」のみで参加 | P39: 和んでどうぞ🤲 | Q39: 日替わりおばんざい3種＋1ドリンク＋店主のスマイル | S39: 800 | T39: 0 | U39: お酒と一品がなくなるまで | AL39: 5 | AM39: {=_xlfn.XLOOKUP($B39,'シート1'!$B$2:$B$70,'シート1'!$A$2:$A$70,"",0,1)} -> 52 | AN39: {=_xlfn.XLOOKUP($B39,'シート1'!$B$2:$B$70,'シート1'!C$2:C$70,"",0,1)} -> ただいま！と言えるおばんざい処 | AO39: {=_xlfn.XLOOKUP($B39,'シート1'!$B$2:$B$70,'シート1'!D$2:D$70,"",0,1)} -> https://www.instagram.com/nagondeyaaa | AP39: {=_xlfn.XLOOKUP($B39,'シート1'!$B$2:$B$70,'シート1'!E$2:E$70,"",0,1)} -> 大阪市大正区三軒家東１丁目２１−１５ | AQ39: {=_xlfn.XLOOKUP($B39,'シート1'!$B$2:$B$70,'シート1'!F$2:F$70,"",0,1)} -> https://maps.app.goo.gl/mPWGsU2dZAaAkywP9
A40: 46324.705 | B40: Fine | C40: 参加する | D40: 駅前 | E40: スナック | F40: テーブルあり | G40: ひと休み | H40: テイクアウト不可 | I40: 日曜日, 火曜日, 水曜日, 木曜日, 金曜日, 土曜日 | J40: 0.20833333 | K40: 0 | L40: 17時から20時ママ1人 | M40: 現金 | N40: いいえ、希望しません。 | O40: 「酔いどれセット」のみで参加 | P40: 1000円引き | Q40: お支払い金額から1000引き | S40: セット代4000円＋ドリンク代 | T40: セット代＋ドリンク代 | U40: 限定なし | AL40: 5 | AM40: {=_xlfn.XLOOKUP($B40,'シート1'!$B$2:$B$70,'シート1'!$A$2:$A$70,"",0,1)} -> 39 | AN40: {=_xlfn.XLOOKUP($B40,'シート1'!$B$2:$B$70,'シート1'!C$2:C$70,"",0,1)} -> 日曜日、祝日もやってまーす！ | AO40: {=_xlfn.XLOOKUP($B40,'シート1'!$B$2:$B$70,'シート1'!D$2:D$70,"",0,1)} -> https://www.instagram.com/fine.r11123 | AP40: {=_xlfn.XLOOKUP($B40,'シート1'!$B$2:$B$70,'シート1'!E$2:E$70,"",0,1)} -> 大阪市大正区三軒家東1-2-6 サンコークリスタル701 | AQ40: {=_xlfn.XLOOKUP($B40,'シート1'!$B$2:$B$70,'シート1'!F$2:F$70,"",0,1)}
...

Sheet シート1
A1: ID | B1: 店舗名 | C1: キャッチコピー | D1: Instagram | E1: 住所 | F1: googlemap
A2: 1 | B2: Tようび | C2: 牛すじとお酒とおばんざい | D2: https://www.instagram.com/t_youbi_ | E2: 大阪市大正区三軒家西１丁目４−１５ 大正コペンシルビル 2F | F2: https://maps.app.goo.gl/zEmF7y9d2rdJpG8a7
A3: 2 | B3: バーガー酒場ハンバーガー・ママ | C3: 一品と酒とグルメバーガー | D3: https://www.instagram.com/hamburger.mama | E3: 大阪市大正区三軒家東１丁目１０−２０ | F3: https://maps.app.goo.gl/LvrTR4thHgoGpoRc7
A4: 3 | B4: 大正焼肉SUNナスビ!! | C4: 通える高級焼肉 | D4: https://www.instagram.com/sunnasubi0675085821 | E4: 大阪市大正区三軒家東１丁目５−１０ | F4: https://maps.app.goo.gl/9DHWbdXcG6VwQRg17
A5: 4 | B5: 大正居酒屋タイガーパンチ | C5: 創作ガチ中華 | D5: https://www.instagram.com/taipan_taisho | E5: 大阪市大正区三軒家東１丁目５−１３ | F5: https://maps.app.goo.gl/wSUzPpSDHh3tzyap6
A6: 5 | B6: ハイエナハイツ | C6: ジビエ・肉料理 | D6: https://www.instagram.com/haiena_haitu | E6: 大阪市大正区三軒家西１丁目５−７ | F6: https://maps.app.goo.gl/JVXGfL5NwG4vKz2t6
A7: 6 | B7: CHWEETS キイロのお店 | C7: クレープ酒場・夜カフェ | D7: https://www.instagram.com/chweets_1138 | E7: 大阪市大正区三軒家西１丁目１７−１７ | F7: https://maps.app.goo.gl/rBmQt912byGEZgbU7
A8: 7 | B8: BAR K'S〜ケーズ〜 | C8: ダーツ・カラオケ | D8: https://www.instagram.com/bar_ks_taisho | E8: 大阪市大正区三軒家西１丁目４−１６ベルコモンズ大正2D | F8: https://maps.app.goo.gl/h1iC1PzMoU3TmyDg9
A9: 8 | B9: Bar Six Nine | C9: ショットバー | D9: https://www.instagram.com/bar_six_nine_0692 | E9: 大阪市大正区三軒家東１丁目５ | F9: https://maps.app.goo.gl/j4hhdwnWPQZ365rk7
A10: 34 | B10: B.B.QホルモンMOU | C10: 立ち飲み・ホルモン | D10: https://www.instagram.com/bbq.mou.29 | E10: 大阪市大正区三軒家東１丁目２−４ | F10: https://maps.app.goo.gl/kCXY14AkjvY7xeAX8
A11: 9 | B11: だしと鶏ちゃぼ大正店 | C11: 焼き鳥・お出汁料理 | D11: https://www.instagram.com/chabo_taisho | E11: 大阪市大正区三軒家東１丁目１７−１６ | F11: https://maps.app.goo.gl/a9AcRcjV9q895Jeo6
A12: 10 | B12: ふじわら君 | C12: 創作料理居酒屋 | D12: https://www.instagram.com/fujiwarakun_taisho | E12: 大阪市大正区三軒家西１丁目１−７ | F12: https://maps.app.goo.gl/svhsvpjHHy4Wfxv49
A13: 11 | B13: 大正サロン髭とボヰン | C13: 立ち飲み・創作料理 | D13: https://www.instagram.com/hige_to.boin | E13: 大阪市大正区三軒家東１丁目５−１４ | F13: https://maps.app.goo.gl/SGWcKvKGnM5jmSea6
... A25: 23 | B25: 大正焼肉ホルモンK2+ | C25: 焼肉ホルモン・韓国料理 | D25: https://www.instagram.com/yakiniku.k2plus | E25: 大阪市大正区三軒家西１丁目９−３６ | F25: https://maps.app.goo.gl/9Wt44gRpXPDoTt1q9
A26: 24 | B26: 呑み処 三日月 | C26: カラオケ居酒屋 | D26: https://www.instagram.com/moon.3.3.3 | E26: 大阪市大正区三軒家東１丁目４−８
A27: 25 | B27: 呑笑戎屋 | C27: 地元親子の大衆居酒屋 | D27: https://www.instagram.com/ebisuya.taisyo | E27: 大阪市大正区三軒家東１丁目５－１０
A28: 26 | B28: 三ちゃん | C28: 海鮮居酒屋 | D28: https://www.instagram.com/sanchan.o2 | E28: 大阪市大正区三軒家西１丁目１７−２０ | F28: https://maps.app.goo.gl/DXhUb1vmR7aNUMMT8
A29: 27 | B29: SoundBar花いち | C29: カラオケバー | D29: https://www.instagram.com/soundbar__hanaichi | E29: 大阪市大正区三軒家東１丁目５−１４ 2階 | F29: https://maps.app.goo.gl/typkWCnoPJKCUWyH8
A30: 28 | B30: ザ·沖縄 | C30: 沖縄料理・カラオケ居酒屋 | D30: https://www.instagram.com/za.okinawa | E30: 大阪市大正区三軒家東１丁目５−１０ | F30: https://maps.app.goo.gl/Prnu5oBX6hyQzpft6
A31: 35 | B31: NONA | C31: ホットサンド・カフェバー | D31: https://www.instagram.com/cafe.bar.nona9 | E31: 大阪市大正区泉尾２丁目１１−９ | F31: https://maps.app.goo.gl/hsSrRGzYZdxe5zo27
A32: 29 | B32: 魚と沖縄料理 えっせんす | C32: お酒は地球を救う | D32: https://www.instagram.com/essence_taishou | E32: 大阪市大正区泉尾３丁目１２−１７ 泉尾商店 街内 | F32: https://maps.app.goo.gl/NL1uEH8kq3MhMEzdA
A33: 30 | B33: Bar Coco-Color | C33: カジュアルバー | D33: https://www.instagram.com/bar_cococolor_taisho | E33: 大阪市大正区三軒家西１丁目１６−１６ | F33: https://maps.app.goo.gl/95uXqnFcfkMM8Jwo8
A34: 31 | B34: 福人(ふくんちゅ) | C34: 作りたいもん作りまっせ居酒屋 | D34: https://www.instagram.com/fuku__nchu | E34: 大阪市大正区三軒家東１丁目１６−２６ | F34: https://maps.app.goo.gl/PB2QxJm3seTe8PFH6
A35: 32 | B35: TM’s DINER | C35: イタリアン・メキシカン・アメリカン | D35: https://www.instagram.com/tms_diner_osaka | E35: 大阪市大正区三軒家東１丁目２−５ 2F | F35: https://maps.app.goo.gl/qM8P7SU6UqcARZm29
A36: 33 | B36: Pizzeria Legare | C36: 本格ピッツァ・ドイツワイン | D36: https://www.instagram.com/pizzerialegare | E36: 大阪市大正区平尾５丁目１２−１６ | F36: https://maps.app.goo.gl/e85zQpDRWme5xsyr6
A37: 36 | B37: 大正お好み屋 ままま | C37: 隠れ家的なお好み焼き | D37: https://www.instagram.com/okonomiyaki_mamama15 | E37: 大阪市大正区三軒家東１丁目１７−３３ 2F
A38: 37 | B38: スナック チェリー | C38: ゴルフ好き集まれ | D38: https://www.instagram.com/cherry.taisho | E38: 大阪市大正区三軒家東１丁目１６ー１６ 2階
A39: 38 | B39: SNACK 2軒め の〜てんき | C39: 楽しく呑めて歌える憩いの場 | D39: https://www.instagram.com/__2knme0703 | E39: 大阪市大正区三軒家西１丁目４−１６ベルコモンズ大正
A40: 39 | B40: Fine | C40: 日曜日、祝日もやってまーす！ | D40: https://www.instagram.com/fine.r11123 | E40: 大阪市大正区三軒家東1-2-6 サンコークリスタル701
A41: 40 | B41: BAR EDIT | C41: お酒&カルチャー発信場所 | D41: https://www.instagram.com/bar_edit_osaka | E41: 大阪市大正区泉尾１丁目３０−１５ 平本ビル | F41: https://maps.app.goo.gl/o8GMyay7XvnYpEwk7
A42: 41 | B42: うおしんのご愛嬌 | C42: 中央市場の魚屋さんが運営する居酒屋 | D42: https://www.instagram.com/uoshin_no_goaikyou | E42: 大阪市大正区三軒家東１丁目１０−２１ | F42: https://maps.app.goo.gl/fFoJbFKog8RT85k2A
A43: 42 | B43: 9回の表 | C43: 生演奏で歌えるバー | D43: https://www.instagram.com/9kaino_omote | E43: 大阪市大正区泉尾４丁目４−１ | F43: https://maps.app.goo.gl/omY9WnpdAGAU7iFX6
A44: 43 | B44: 石窯バール デコレ | C44: 本格石窯料理・ベルギービール | D44: https://www.instagram.com/decore.taisho | E44: 大阪市大正区三軒家西１丁目５−１０ | F44: https://maps.app.goo.gl/wwd3JawbhkNotrCY8
A45: 44 | B45: 鉄板焼き ぷれこ | C45: 変態植物倶楽部の店 | D45: https://www.instagram.com/pureko.yakisoba___ | E45: 大阪市大正区泉尾１丁目２２−１２ | F45: https://maps.app.goo.gl/7LxwLtzxhZXxzxw59
A46: 45 | B46: かのじょとカレー | C46: デートの行き先、カレー屋 | D46: https://www.instagram.com/sheandcurry | E46: 大阪市大正区泉尾１丁目３０−１５ 平本ビル
A47: 46 | B47: 呑め屋 集合！ | C47: 素朴な家庭料理 | D47: https://www.instagram.com/syuugo_ma_0418 | E47: 大阪市大正区泉尾5丁目２－２
A48: 47 | B48: お好み焼き 竹ちゃん | C48: お好み焼き・焼きそば・一品 | D48: https://www.instagram.com/takechan8989 | E48: 大阪市大正区泉尾４丁目４−１ 中山ビル 1階
A49: 48 | B49: 大正焼肉 ホルモン焼みやけ | C49: 国産牛新鮮ホルモン焼 | D49: https://www.instagram.com/horumonyaki_miyake | E49: 大阪市大正区三軒家東１丁目１０−２２ 1階 | F49: https://maps.app.goo.gl/vtyUhfcTtNvREszDA
A50: 49 | B50: 酒と魚 喰海~KUKAI~ | C50: 安くて美味い変な魚屋さん | D50: https://www.instagram.com/kukai_izakaya_ | E50: 大阪市大正区千島３丁目３−１２ シティハイツ大正 | F50: https://maps.app.goo.gl/2SUDVhYEkfnGQu8q9
A51: 50 | B51: Zakky's ホットドッグ | C51: 大正アメリンカンダイナー | D51: https://www.instagram.com/zakkys_hotdog | E51: 大阪市大正区千島３丁目１２−１３ ハイグレード千島 | F51: https://maps.app.goo.gl/UVjYbt57Dy43WcJN9
...
